[2025-02-12T02:53:34.055+0000] {local_task_job_runner.py:123} INFO - ::group::Pre task execution logs
[2025-02-12T02:53:34.066+0000] {taskinstance.py:2613} INFO - Dependencies all met for dep_context=non-requeueable deps ti=<TaskInstance: LocalIngestionDag.ingest manual__2025-02-12T02:53:26.031437+00:00 [queued]>
[2025-02-12T02:53:34.070+0000] {taskinstance.py:2613} INFO - Dependencies all met for dep_context=requeueable deps ti=<TaskInstance: LocalIngestionDag.ingest manual__2025-02-12T02:53:26.031437+00:00 [queued]>
[2025-02-12T02:53:34.070+0000] {taskinstance.py:2866} INFO - Starting attempt 1 of 1
[2025-02-12T02:53:34.078+0000] {taskinstance.py:2889} INFO - Executing <Task(PythonOperator): ingest> on 2025-02-12 02:53:26.031437+00:00
[2025-02-12T02:53:34.081+0000] {warnings.py:112} WARNING - /home/***/.local/lib/python3.12/site-packages/***/task/task_runner/standard_task_runner.py:70: DeprecationWarning: This process (pid=849) is multi-threaded, use of fork() may lead to deadlocks in the child.
  pid = os.fork()

[2025-02-12T02:53:34.082+0000] {standard_task_runner.py:72} INFO - Started process 850 to run task
[2025-02-12T02:53:34.082+0000] {standard_task_runner.py:104} INFO - Running: ['***', 'tasks', 'run', 'LocalIngestionDag', 'ingest', 'manual__2025-02-12T02:53:26.031437+00:00', '--job-id', '126', '--raw', '--subdir', 'DAGS_FOLDER/data_ingestion_local.py', '--cfg-path', '/tmp/tmpotq61tw9']
[2025-02-12T02:53:34.084+0000] {standard_task_runner.py:105} INFO - Job 126: Subtask ingest
[2025-02-12T02:53:34.116+0000] {task_command.py:467} INFO - Running <TaskInstance: LocalIngestionDag.ingest manual__2025-02-12T02:53:26.031437+00:00 [running]> on host daeebf3e3edd
[2025-02-12T02:53:34.159+0000] {taskinstance.py:3132} INFO - Exporting env vars: AIRFLOW_CTX_DAG_OWNER='***' AIRFLOW_CTX_DAG_ID='LocalIngestionDag' AIRFLOW_CTX_TASK_ID='ingest' AIRFLOW_CTX_EXECUTION_DATE='2025-02-12T02:53:26.031437+00:00' AIRFLOW_CTX_TRY_NUMBER='1' AIRFLOW_CTX_DAG_RUN_ID='manual__2025-02-12T02:53:26.031437+00:00'
[2025-02-12T02:53:34.159+0000] {taskinstance.py:731} INFO - ::endgroup::
[2025-02-12T02:53:34.168+0000] {taskinstance.py:3311} ERROR - Task failed with exception
Traceback (most recent call last):
  File "/home/airflow/.local/lib/python3.12/site-packages/airflow/models/taskinstance.py", line 767, in _execute_task
    result = _execute_callable(context=context, **execute_callable_kwargs)
             ^^^^^^^^^^^^^^^^^^^^^^^^^^^^^^^^^^^^^^^^^^^^^^^^^^^^^^^^^^^^^
  File "/home/airflow/.local/lib/python3.12/site-packages/airflow/models/taskinstance.py", line 733, in _execute_callable
    return ExecutionCallableRunner(
           ^^^^^^^^^^^^^^^^^^^^^^^^
  File "/home/airflow/.local/lib/python3.12/site-packages/airflow/utils/operator_helpers.py", line 252, in run
    return self.func(*args, **kwargs)
           ^^^^^^^^^^^^^^^^^^^^^^^^^^
  File "/home/airflow/.local/lib/python3.12/site-packages/airflow/models/baseoperator.py", line 422, in wrapper
    return func(self, *args, **kwargs)
           ^^^^^^^^^^^^^^^^^^^^^^^^^^^
  File "/home/airflow/.local/lib/python3.12/site-packages/airflow/operators/python.py", line 238, in execute
    return_value = self.execute_callable()
                   ^^^^^^^^^^^^^^^^^^^^^^^
  File "/home/airflow/.local/lib/python3.12/site-packages/airflow/operators/python.py", line 256, in execute_callable
    return runner.run(*self.op_args, **self.op_kwargs)
           ^^^^^^^^^^^^^^^^^^^^^^^^^^^^^^^^^^^^^^^^^^^
  File "/home/airflow/.local/lib/python3.12/site-packages/airflow/utils/operator_helpers.py", line 252, in run
    return self.func(*args, **kwargs)
           ^^^^^^^^^^^^^^^^^^^^^^^^^^
  File "/opt/airflow/dags/ingest_script.py", line 17, in ingest_callable
    table = pv.read_csv(csv_name)
            ^^^^^^^^^^^^^^^^^^^^^
  File "pyarrow/_csv.pyx", line 1256, in pyarrow._csv.read_csv
  File "pyarrow/_csv.pyx", line 1115, in pyarrow._csv._get_reader
  File "pyarrow/io.pxi", line 2188, in pyarrow.lib.get_input_stream
  File "pyarrow/io.pxi", line 2159, in pyarrow.lib.get_native_file
  File "pyarrow/io.pxi", line 1245, in pyarrow.lib.OSFile.__cinit__
  File "pyarrow/io.pxi", line 1257, in pyarrow.lib.OSFile._open_readable
  File "pyarrow/error.pxi", line 155, in pyarrow.lib.pyarrow_internal_check_status
  File "pyarrow/error.pxi", line 92, in pyarrow.lib.check_status
FileNotFoundError: [Errno 2] Failed to open local file 'output.csv'. Detail: [errno 2] No such file or directory
[2025-02-12T02:53:34.175+0000] {taskinstance.py:1225} INFO - Marking task as FAILED. dag_id=LocalIngestionDag, task_id=ingest, run_id=manual__2025-02-12T02:53:26.031437+00:00, execution_date=20250212T025326, start_date=20250212T025334, end_date=20250212T025334
[2025-02-12T02:53:34.272+0000] {taskinstance.py:340} INFO - ::group::Post task execution logs
[2025-02-12T02:53:34.272+0000] {standard_task_runner.py:124} ERROR - Failed to execute job 126 for task ingest ([Errno 2] Failed to open local file 'output.csv'. Detail: [errno 2] No such file or directory; 850)
Traceback (most recent call last):
  File "/home/airflow/.local/lib/python3.12/site-packages/airflow/task/task_runner/standard_task_runner.py", line 117, in _start_by_fork
    ret = args.func(args, dag=self.dag)
          ^^^^^^^^^^^^^^^^^^^^^^^^^^^^^
  File "/home/airflow/.local/lib/python3.12/site-packages/airflow/cli/cli_config.py", line 49, in command
    return func(*args, **kwargs)
           ^^^^^^^^^^^^^^^^^^^^^
  File "/home/airflow/.local/lib/python3.12/site-packages/airflow/utils/cli.py", line 116, in wrapper
    return f(*args, **kwargs)
           ^^^^^^^^^^^^^^^^^^
  File "/home/airflow/.local/lib/python3.12/site-packages/airflow/cli/commands/task_command.py", line 483, in task_run
    task_return_code = _run_task_by_selected_method(args, _dag, ti)
                       ^^^^^^^^^^^^^^^^^^^^^^^^^^^^^^^^^^^^^^^^^^^^
  File "/home/airflow/.local/lib/python3.12/site-packages/airflow/cli/commands/task_command.py", line 256, in _run_task_by_selected_method
    return _run_raw_task(args, ti)
           ^^^^^^^^^^^^^^^^^^^^^^^
  File "/home/airflow/.local/lib/python3.12/site-packages/airflow/cli/commands/task_command.py", line 341, in _run_raw_task
    return ti._run_raw_task(
           ^^^^^^^^^^^^^^^^^
  File "/home/airflow/.local/lib/python3.12/site-packages/airflow/utils/session.py", line 97, in wrapper
    return func(*args, session=session, **kwargs)
           ^^^^^^^^^^^^^^^^^^^^^^^^^^^^^^^^^^^^^^
  File "/home/airflow/.local/lib/python3.12/site-packages/airflow/models/taskinstance.py", line 3005, in _run_raw_task
    return _run_raw_task(
           ^^^^^^^^^^^^^^
  File "/home/airflow/.local/lib/python3.12/site-packages/airflow/models/taskinstance.py", line 273, in _run_raw_task
    TaskInstance._execute_task_with_callbacks(
  File "/home/airflow/.local/lib/python3.12/site-packages/airflow/models/taskinstance.py", line 3159, in _execute_task_with_callbacks
    result = self._execute_task(context, task_orig)
             ^^^^^^^^^^^^^^^^^^^^^^^^^^^^^^^^^^^^^^
  File "/home/airflow/.local/lib/python3.12/site-packages/airflow/models/taskinstance.py", line 3183, in _execute_task
    return _execute_task(self, context, task_orig)
           ^^^^^^^^^^^^^^^^^^^^^^^^^^^^^^^^^^^^^^^
  File "/home/airflow/.local/lib/python3.12/site-packages/airflow/models/taskinstance.py", line 767, in _execute_task
    result = _execute_callable(context=context, **execute_callable_kwargs)
             ^^^^^^^^^^^^^^^^^^^^^^^^^^^^^^^^^^^^^^^^^^^^^^^^^^^^^^^^^^^^^
  File "/home/airflow/.local/lib/python3.12/site-packages/airflow/models/taskinstance.py", line 733, in _execute_callable
    return ExecutionCallableRunner(
           ^^^^^^^^^^^^^^^^^^^^^^^^
  File "/home/airflow/.local/lib/python3.12/site-packages/airflow/utils/operator_helpers.py", line 252, in run
    return self.func(*args, **kwargs)
           ^^^^^^^^^^^^^^^^^^^^^^^^^^
  File "/home/airflow/.local/lib/python3.12/site-packages/airflow/models/baseoperator.py", line 422, in wrapper
    return func(self, *args, **kwargs)
           ^^^^^^^^^^^^^^^^^^^^^^^^^^^
  File "/home/airflow/.local/lib/python3.12/site-packages/airflow/operators/python.py", line 238, in execute
    return_value = self.execute_callable()
                   ^^^^^^^^^^^^^^^^^^^^^^^
  File "/home/airflow/.local/lib/python3.12/site-packages/airflow/operators/python.py", line 256, in execute_callable
    return runner.run(*self.op_args, **self.op_kwargs)
           ^^^^^^^^^^^^^^^^^^^^^^^^^^^^^^^^^^^^^^^^^^^
  File "/home/airflow/.local/lib/python3.12/site-packages/airflow/utils/operator_helpers.py", line 252, in run
    return self.func(*args, **kwargs)
           ^^^^^^^^^^^^^^^^^^^^^^^^^^
  File "/opt/airflow/dags/ingest_script.py", line 17, in ingest_callable
    table = pv.read_csv(csv_name)
            ^^^^^^^^^^^^^^^^^^^^^
  File "pyarrow/_csv.pyx", line 1256, in pyarrow._csv.read_csv
  File "pyarrow/_csv.pyx", line 1115, in pyarrow._csv._get_reader
  File "pyarrow/io.pxi", line 2188, in pyarrow.lib.get_input_stream
  File "pyarrow/io.pxi", line 2159, in pyarrow.lib.get_native_file
  File "pyarrow/io.pxi", line 1245, in pyarrow.lib.OSFile.__cinit__
  File "pyarrow/io.pxi", line 1257, in pyarrow.lib.OSFile._open_readable
  File "pyarrow/error.pxi", line 155, in pyarrow.lib.pyarrow_internal_check_status
  File "pyarrow/error.pxi", line 92, in pyarrow.lib.check_status
FileNotFoundError: [Errno 2] Failed to open local file 'output.csv'. Detail: [errno 2] No such file or directory
[2025-02-12T02:53:34.305+0000] {local_task_job_runner.py:266} INFO - Task exited with return code 1
[2025-02-12T02:53:34.317+0000] {taskinstance.py:3895} INFO - 0 downstream tasks scheduled from follow-on schedule check
[2025-02-12T02:53:34.317+0000] {local_task_job_runner.py:245} INFO - ::endgroup::
